<?xml version="1.0"?>
<robot name="tortoisebot">
<link name="base_link">
    <visual>
        <geometry>
            <box size="0.6 0.3 0.3"/>
        </geometry>
        <material name="silver">
            <color rgba="0.75 0.75 0.75 1"/>
        </material>
    </visual>
    <collision>
        <geometry>
            <box size="0.6 0.3 0.3"/>
        </geometry>
    </collision>
    <inertial>
        <mass value="1.0"/>
        <inertia ixx="0.015" iyy="0.0375" izz="0.0375"
                 ixy="0" iyz="0" ixz="0"/>
    </inertial>
</link>

<link name="front_caster">
    <visual>
        <geometry>
            <box size="0.1 0.1 0.3"/>
        </geometry>
        <material name="silver">
            <color rgba="0.75 0.75 0.75 1"/>
        </material>
    </visual>
    <collision>
        <geometry>
            <box size="0.1 0.1 0.3"/>
        </geometry>
    </collision>
    <inertial>
        <mass value="0.1"/>
        <inertia ixx="0.00083" iyy="0.00083" izz="0.000167"
                 ixy="0" iyz="0" ixz="0"/>
    </inertial>
</link>

<joint name="front_caster_joint" type="continuous">
    <axis xyz="0 0 1"/>
    <parent link="base_link"/>
    <child link="front_caster"/>
    <origin rpy="0 0 0" xyz="0.3 0 0"/>
</joint>

<link name="front_wheel">
    <visual>
        <geometry>
            <cylinder length="0.05" radius="0.035"/>
        </geometry>
        <material name="black">
            <color rgba="0.75 0 0 1"/>
        </material>
    </visual>
    <collision>
        <geometry>
            <cylinder length="0.05" radius="0.035"/>
        </geometry>
    </collision>
    <inertial>
        <mass value="0.1"/>
        <inertia ixx="5.1458e-5" iyy="5.1458e-5" izz="6.125e-5"
                 ixy="0" iyz="0" ixz="0"/>
    </inertial>
</link>

<joint name="front_wheel_joint" type="continuous">
    <axis xyz="0 0 1"/>
    <parent link="front_caster"/>
    <child link="front_wheel"/>
    <origin rpy="-1.5708 0 0" xyz="0.05 0 -0.15"/>
</joint>

<link name="left_wheel">
    <visual>
        <geometry>
            <cylinder length="0.05" radius="0.035"/>
        </geometry>
        <material name="black"/>
    </visual>
    <collision>
        <geometry>
            <cylinder length="0.05" radius="0.035"/>
        </geometry>
    </collision>
    <inertial>
        <mass value="0.1"/>
        <inertia ixx="5.1458e-5" iyy="5.1458e-5" izz="6.125e-5"
                 ixy="0" iyz="0" ixz="0"/>
    </inertial>
</link>

<joint name="left_wheel_joint" type="continuous">
    <axis xyz="0 0 1"/>
    <parent link="base_link"/>
    <child link="left_wheel"/>
    <origin rpy="-1.5708 0 0" xyz="-0.2825 0.125 -0.15"/>
</joint>

<link name="right_wheel">
    <visual>
        <geometry>
            <cylinder length="0.05" radius="0.035"/>
        </geometry>
        <material name="black"/>
    </visual>
    <collision>
        <geometry>
            <cylinder length="0.05" radius="0.035"/>
        </geometry>
    </collision>
    <inertial>
        <mass value="0.1"/>
        <inertia ixx="5.1458e-5" iyy="5.1458e-5" izz="6.125e-5"
                 ixy="0" iyz="0" ixz="0"/>
    </inertial>
</link>

<joint name="right_wheel_joint" type="continuous">
    <axis xyz="0 0 1"/>
    <parent link="base_link"/>
    <child link="right_wheel"/>
    <origin rpy="-1.5708 0 0" xyz="-0.2825 -0.125 -0.15"/>
</joint>

<gazebo>
    <plugin name="differential_drive_controller"
            filename="libgazebo_ros_diff_drive.so">
    <leftJoint>left_wheel_joint</leftJoint>
    <rightJoint>right_wheel_joint</rightJoint>
    <robotBaseFrame>base_link</robotBaseFrame>
    <wheelSeperation>0.25</wheelSeperation>
    <wheelSeperation>0.07</wheelSeperation>
    <publishWheelJointState>true</publishWheelJointState>
    </plugin>

    <plugin name="joint_state_publisher"
    filename="libgazebo_ros_joint_state_publisher.so">
        <jointName>front_caster_joint, front_wheel_joint</jointName>
    </plugin>
</gazebo>

<link name="camera_link">
    <collision>
        <origin xyz="0 0 0" rpy="0 0 0"/>
        <geometry>
            <box size="0.1 0.1 0.1"/>
        </geometry>
    </collision>
    <visual>
        <origin xyz="0 0 0" rpy="0 0 0"/>
        <geometry>
            <box size="0.1 0.1 0.1"/>
        </geometry>
    </visual>
    <inertial>
        <mass value="1e-5" />
        <origin xyz="0 0 0" rpy="0 0 0"/>
        <inertia ixx="1e-6" ixy="0" ixz="0" iyy="1e-6" iyz="0" izz="1e-6" />
    </inertial>
</link>
<joint name="camera_joint" type="fixed">
    <axis xyz="0 1 0" />
    <origin xyz="0 0 0.2" rpy="0 0 0"/>
    <parent link="base_link"/>
    <child link="camera_link"/>
</joint>

<gazebo reference="camera_link">
  <sensor name="$camera_link_camera" type="depth">
    <update_rate>20</update_rate>
    <camera>
      <horizontal_fov>1.047198</horizontal_fov>
      <image>
        <width>640</width>
        <height>480</height>
        <format>R8G8B8</format>
      </image>
      <clip>
        <near>0.05</near>
        <far>3</far>
      </clip>
    </camera>
    <plugin name="camera_link_controller" filename="libgazebo_ros_openni_kinect.so">
      <baseline>0.2</baseline>
      <alwaysOn>true</alwaysOn>
      <updateRate>1.0</updateRate>
      <cameraName>depth_camera_ir</cameraName>
      <imageTopicName>/depth_camera/color/image_raw</imageTopicName>
      <cameraInfoTopicName>/depth_camera/color/camera_info</cameraInfoTopicName>
      <depthImageTopicName>/depth_camera/depth/image_raw</depthImageTopicName>
      <depthImageInfoTopicName>/depth_camera/depth/camera_info</depthImageInfoTopicName>
      <pointCloudTopicName>/depth_camera/depth/points</pointCloudTopicName>
      <frameName>depth_camera_frame</frameName>
      <pointCloudCutoff>0.5</pointCloudCutoff>
      <pointCloudCutoffMax>3.0</pointCloudCutoffMax>
      <distortionK1>0.00000001</distortionK1>
      <distortionK2>0.00000001</distortionK2>
      <distortionK3>0.00000001</distortionK3>
      <distortionT1>0.00000001</distortionT1>
      <distortionT2>0.00000001</distortionT2>
      <CxPrime>0</CxPrime>
      <Cx>0</Cx>
      <Cy>0</Cy>
      <focalLength>0</focalLength>
      <hackBaseline>0</hackBaseline>
    </plugin>
  </sensor>
</gazebo>

</robot>

